Workbook
Name a: [1]COFF!#REF!
Name b: [1]COFF!#REF!
Name bor: '[2]tableau des coef.'!$D$15:$D$19
Name idem: [3]Information!$G$1:$K$6
Name Liste1: '[2]Tableau de ventilation ex 13'!$D$21:$D$34
Name Niveau: [3]Information!$A$1:$A$9
Name quantité: [1]COFF!#REF!
Name quantité: #REF!
Name surface: [1]COFF!#REF!
Name surface: #REF!
Name TH: [3]Information!$A$1:$D$11
Name zone: [3]Information!$G$2:$G$7

Sheet Notes
B3: ml | C3: 1
B4: m² | C4: 2
B5: m³ | C5: 3
B6: T | C6: 4 | G6: ALT + l + ç + a | I6: COLONNES
B7: kg | C7: 5
B8: l | C8: 6
B9: € | C9: 7 | G9: ALT + l + ç + j | I9: LIGNES
B10: U | C10: 8
B11: ans | C11: 9
B12: % | C12: 10
B13: H
D15: m³ x La densité = Le Tonne
D20: Saisir 1% dans une cellule on copie la cellule Ctrl+c
D21: On séléctionne les nombre à convertir en pourcentge on utilise le raccourci Ctrl+Alt+v
D22: La fenêtre Collage spécial on coche la case multiplication et on clique sur OK
D24: 5000 | E24: 4500 | F24: =(((D24-E24)/D24)*100)*0.01 -> 0.1 | G24: 0.01
F25: =((D24-E24)/D24)*100 -> 10

Sheet CHEMINEMENT
A2: CHEMINEMENT D'UNE ETUDE DE PRIX
B4: MATERIAUX | G4: SALAIRE + CHARGES | L4: MATERIEL AFFECTE
E7: QUANTITATIF | I7: PRIX UNITAIRES D.S
D10: FRAIS DE CHANTIER | I10: DEBOURSES SECS
E13: DEBOURSES TOTAUX | I13: FRAIS DE MARCHE / FRAIS GENERAUX
F16: PRIX DE REVIENT | J16: BENEFICE
E19: T.V.A | H19: PRIX DE VENTE H.T
F22: PRIX DE VENTE T.T.C
E26: ETAPE N°1 | O26: VOIR COUR P31
F27: CALCUL DU C.H.M (coût horaire moyen )
C30: NBR D'HEURES PAR SEMAINE | I30: NBR DE JOURS
C31: ( En générale 35,00 heures / mois ) | I31: ( En général 5 jours / semaine )
F33: DETERMINATION DE L'EQUIPE
F34: ( niveaux de qualifications de chaques ouvriers )
C36: DETERMINATION DE LEURS TARIFS HORAIRES | H36: ATTENTION A LA MAJORATION ( en % )
C37: ( Informations données / legifrance code IDCC 1597 )
C39: DETERMINATION INCIDENCE HEURES SUPPS ( en % ) | H39: POURCENTAGE SUR TARIFS HORAIRES MAJORES
C40: ( données entreprises si exemple 39 H / mois )
C43: (1 ER) TOTAL TARIF HORAIRE + HEURES SUPPS
C46: DETERMINATION TEMPS IMPRODUCTIF ( en % ) | H46: POURCENTAGE SUR (1 ER) TOTAL
C47: ( données entreprises )
C50: TOTAL SALAIRE DE BASE MAJORE
C54: DETERMINATIONS INDEMNITES JOURNALIERES | H54: REPAS | J54: TRAJET | L54: TRANSPORT
C57: TOTAL INDEMNITES x NBRE DE JOURS / NBRE HEURES
C59: PRIMES EVENTUELLES
C62: TOTAL INDEMNITES
C66: DETERMINATION CHARGES SALARIALES
C69: CHARGES SUR TOTAL SALAIRES MAJORE
C70: ( en gégérale 80 % du salaire )
C72: CHARGES SUR TOTAL INDEMNITES
C73: ( en générale 56 % des indemnités )
C76: TOTAL DES CHARGES
J78: COUT HORAIRE DE MAIN D'ŒUVRE/QUALIFS
J81: DETERMINATION DU NBR DE PERSONNES / QUALIFS
C84: COUT HORAIRE DE L'EQUIPE | J84: TOTAL COUT HORAIRE / QUALIFS
G85: ( somme des salaires de l'équipe )
C87: NBR DE PERSONNES TOTAL
F90: COUT HORAIRE MOYEN | K90: REFERENCE TABLEAU N°1
E94: ETAPE N° 2 | O94: VOIR COUR P32
E96: TEMPS UNITAIRE A PARTIR DE DONNEES D'UN CHANTIER
...

Sheet ÉTUDE DE PRIX
C4: Matériaux | E4: Salaires + Charges | H4: Matériel affecté
D6: Quantitatif | F6: Prix Unitaires D.S.
C8: Frais de chantier | F8: Déboursés secs
D10: Déboursés totaux | G10: Frais de marché
G11: Frais généraux
E13: Prix de revient | H13: Bénéfice
D15: T.V.A. | F15: Prix de vente H.T.
E17: Prix de vente T.T.C.
B37: DEVIS ESTIMATIF
C40: Projet : | E40: Coefficient de règlement :
C41: code | D41: désignation des ouvrages | E41: U | F41: quantités | G41: déboursés secs | I41: prix de vente H.T.
G42: P.U. | H42: montant 4 x 5 | I42: P.U. 5 x coef. | J42: montant 4 x 7
C44: 1 | D44: 2 | E44: 3 | F44: 4 | G44: 5 | H44: 6 | I44: 7 | J44: 8
C47: Le montant des déboursés secs | E47: = | F47: Les quantités | G47: x | H47: Le prix unitaire
C49: Le prix de vente HT d'un prix unitaire | E49: = | F49: Le prix unitaire | G49: x | H49: Coefficient de règlement
C51: Le montant de prix de vente HT | E51: = | F51: Les quantités | G51: x | H51: Le prix de vente HT d'un prix unitaire
B56: MAIN D'OEUVRE
D59: La grille de salaires des ouvriers du BTP en 2024
C62: Niveau I : ouvriers d’exécution
C63: Niveau II : ouvriers professionnels
C64: Niveau III : compagnons professionnels
C65: Niveau IV : maîtres d’œuvre et chefs d’équipe
C68: Catégorie Professionnelle | E68: Coefficient | F68: Salaire mensuel brut minimum | H68: Taux horaire
B69: OE 1 | C69: Niveau I - Position 1 | E69: 150 | F69: 1766.92 | H69: 11.65
B70: OE 2 | C70: Niveau I - Position 2 | E70: 170 | F70: 1768 | H70: 11.6568
B71: OP | C71: Niveau II | E71: 185 | F71: 1828 | H71: 12.0524
B72: CP 1 | C72: Niveau III - Position 1 | E72: 210 | F72: 2000 | H72: 13.1865
B73: CP 2 | C73: Niveau III - Position 2 | E73: 230 | F73: 2138 | H73: 14.0963
B74: CE 1 | C74: Niveau IV - Position 1 | E74: 250 | F74: 2277 | H74: 15.0128
B75: CE 2 | C75: Niveau IV - Position 2 | E75: 270 | F75: 2415 | H75: 15.9227
J76: 1 | K76: SALAIRE DE BASE HORAIRE
J77: 2 | K77: Incidence heures supplémentaires
D78: La grille de salaires des employés ETAM du BTP en 2024 | K78: exprimé en pourcentage sur (1)=
J79: 3 | K79: Ensemble (1) + (2) =
J80: 4 | K80: Temps improductif: % sur (3):
C81: Classification | E81: Salaire mensuel brut minimum | J81: 5 | K81: TOTAL (3) + (4) =
C82: A | E82: 1766.92 | K82: Indemnités journalières ramenées à l'heure:
C83: B | E83: 1812 | K83: REPAS
C84: C | E84: 1909 | K84: TRANSPORT
C85: D | E85: 2086 | K85: TRAJET
...

Sheet Questionnaire
A1: Questionnaire

Sheet (C.H.M) MAIN D'OEUVRE
B2: Chantier: | C2: 1 | G2: Zone: | I2: Date: | J2: =TODAY() -> 46093
B4: CALCUL DU COUT HORAIRE DE LA MAIN D'ŒUVRE
B5: ORGANISATION DU TRAVAIL HEBDOMADAIRE: | G5: 35 | H5: Heures en | I5: 5 | J5: jours
B6: ELEMENTS DU SALAIRE | G6: Qualification main d'oeuvre
B9: SALAIRE DE BASE HORAIRE | F9: 1 | G9: =VLOOKUP(G7,'ÉTUDE DE PRIX'!B69:H75,7,FALSE)*F9 -> #N/A | H9: =VLOOKUP(H7,'ÉTUDE DE PRIX'!B69:H75,7,FALSE)*F9 -> #N/A | I9: =VLOOKUP(I7,'ÉTUDE DE PRIX'!B69:H75,7,FALSE)*F9 -> #N/A | J9: =VLOOKUP(J7,'ÉTUDE DE PRIX'!B69:H75,7,FALSE)*F9 -> #N/A
B11: Incidence heures supplémentaires
F12: =(IF(G5<35,1,IF(G5<43,(35+(G5-35)*1.25)/G5,(35+8*1.25+(G5-43)*1.5+G5))-1)*100) -> 0 | G12: =ROUND(G9*$F$12%,2) -> #N/A | H12: =ROUND(H9*$F$12%,2) -> #N/A | I12: =ROUND(I9*$F$12%,2) -> #N/A | J12: =ROUND(J9*$F$12%,2) -> #N/A
B14: Ensemble | G14: =G9+G12 -> #N/A | H14: =H9+H12 -> #N/A | I14: =I9+I12 -> #N/A | J14: =J9+J12 -> #N/A
B16: Temps improductif | F16: 0 | G16: =ROUND(G14*$F$16%,2) -> #N/A | H16: =ROUND(H14*$F$16%,2) -> #N/A | I16: =ROUND(I14*$F$16%,2) -> #N/A | J16: =ROUND(J14*$F$16%,2) -> #N/A
B18: TOTAL | G18: =G14+G16 -> #N/A | H18: =H14+H16 -> #N/A | I18: =I14+I16 -> #N/A | J18: =J14+J16 -> #N/A
B20: Indemnités journalières ramenées à l'heure:
B21: REPAS | G21: =VLOOKUP(H2,'ÉTUDE DE PRIX'!C96:G101,3,FALSE) -> #N/A | H21: =VLOOKUP(H2,'ÉTUDE DE PRIX'!C96:G101,3,FALSE) -> #N/A | I21: =VLOOKUP(H2,'ÉTUDE DE PRIX'!C96:G101,3,FALSE) -> #N/A | J21: =VLOOKUP(H2,'ÉTUDE DE PRIX'!C96:G101,3,FALSE) -> #N/A
B22: TRANSPORT | G22: =VLOOKUP(H2,'ÉTUDE DE PRIX'!C96:G101,4,FALSE) -> #N/A | H22: =VLOOKUP(H2,'ÉTUDE DE PRIX'!C96:G101,4,FALSE) -> #N/A | I22: =VLOOKUP(H2,'ÉTUDE DE PRIX'!C96:G101,4,FALSE) -> #N/A | J22: =VLOOKUP(H2,'ÉTUDE DE PRIX'!C96:G101,4,FALSE) -> #N/A
B23: TRAJET | G23: =VLOOKUP(H2,'ÉTUDE DE PRIX'!C96:G101,5,FALSE) -> #N/A | H23: =VLOOKUP(H2,'ÉTUDE DE PRIX'!C96:G101,5,FALSE) -> #N/A | I23: =VLOOKUP(H2,'ÉTUDE DE PRIX'!C96:G101,5,FALSE) -> #N/A | J23: =VLOOKUP(H2,'ÉTUDE DE PRIX'!C96:G101,5,FALSE) -> #N/A
B24: Total | G24: =SUM(G21:G23) -> #N/A | H24: =SUM(H21:H23) -> #N/A | I24: =SUM(I21:I23) -> #N/A | J24: =SUM(J21:J23) -> #N/A
B27: Total Nbre de jours / Nbre d'heures | G27: =IF($G$5="","",ROUND(SUM($G$21:$G$23)*$I$5/$G$5,2)) -> #N/A | H27: =IF($G$5="","",ROUND(SUM($G$21:$G$23)*$I$5/$G$5,2)) -> #N/A | I27: =IF($G$5="","",ROUND(SUM($G$21:$G$23)*$I$5/$G$5,2)) -> #N/A | J27: =IF($G$5="","",ROUND(SUM($G$21:$G$23)*$I$5/$G$5,2)) -> #N/A
B29: Primes diverses ramenées à l'heure
B30: (outillage, salissure, etc...)
B32: TOTAL Indemnités + primes | G32: =SUM(G27:G31) -> #N/A | H32: =SUM(H27:H31) -> #N/A | I32: =SUM(I27:I31) -> #N/A | J32: =SUM(J27:J31) -> #N/A
B36: CHARGES SALARIALES | F36: 80 | G36: =ROUND(G18*$F$36%,2) -> #N/A | H36: =ROUND(H18*$F$36%,2) -> #N/A | I36: =ROUND(I18*$F$36%,2) -> #N/A | J36: =ROUND(J18*$F$36%,2) -> #N/A
B38: Sur indemnités | F38: 56 | G38: =ROUND(G32*$F$38%,2) -> #N/A | H38: =ROUND(H32*$F$38%,2) -> #N/A | I38: =ROUND(I32*$F$38%,2) -> #N/A | J38: =ROUND(J32*$F$38%,2) -> #N/A
B40: TOTAL DES CHARGES | G40: =G38+G36 -> #N/A | H40: =H38+H36 -> #N/A | I40: =I38+I36 -> #N/A | J40: =J38+J36 -> #N/A
B42: COUT HORAIRE DE MAIN D'OEUVRE | G42: =G40+G32+G18 -> #N/A | H42: =H40+H32+H18 -> #N/A | I42: =I40+I32+I18 -> #N/A | J42: =J40+J32+J18 -> #N/A
B45: Nombre de personnes:
B47: TOTAL | G47: =G42*G45 -> #N/A | H47: =H42*H45 -> #N/A | I47: =I42*I45 -> #N/A | J47: =J42*J45 -> #N/A
B48: COUT HORAIRE DE L'EQUIPE | G48: =SUM(G47:J47) -> #N/A
B49: COUT HORAIRE MOYEN | G49: =IF(SUM(G45:J45)=0,"",ROUND(G48/SUM(G45:J45),2))

Sheet COÛT DES MATÉRIAUX
A1: Chantier: | B1: ='(C.H.M) MAIN D''OEUVRE'!C2 -> 1 | Q1: COÛT MO : | U1: 0 | X1: Date: | Y1: =TODAY() -> 46093
A2: DESIGNATION DES MATERIAUX | E2: PERTES | G2: ACHAT | H2: COUT DU TRANSPORT | Q2: COUT DU DECHARGEMENT | Z2: PRIX UNITAIRE RENDU CHANTIER
A3: Désignation des matériaux | B3: Fournsseurs Provenance | C3: Quantités prévues | D3: Unité | E3: % | F3: Coef | G3: Prix d'achat unitaire H.T | H3: Terme horaire | K3: Terme kilométrique | N3: Prix d'un voyage | O3: Quant.par voyage | P3: Prix unitaire du transport | Q3: Main d'œuvre | T3: Matériel | W3: TOTAL frais de manutent | X3: Quantité manutent | Y3: Prix unitaire de manutent
H4: Nbre heures | I4: Prix de l'heure | J4: TOTAL | K4: Nbre de km | L4: Prix du km | M4: TOTAL | Q4: Nbre heures | R4: Prix de l'heure | S4: TOTAL M.O | T4: Nbre | U4: Prix de location | V4: TOTAL
J6: 8 x 9 | M6: 11 x 12 | N6: 10 + 13 | P6: 14 / 15 | S6: 17 x 18 | V6: 20 x 21 | W6: 19 + 22 | Y6: 23 / 24 | Z6: 7 + 16 + 25
A7: 1 | B7: 2 | C7: 3 | D7: 4 | E7: 5 | F7: 6 | G7: 7 | H7: 8 | I7: 9 | J7: 10 | K7: 11 | L7: 12 | M7: 13 | N7: 14 | O7: 15 | P7: 16 | Q7: 17 | R7: 18 | S7: 19 | T7: 20 | U7: 21 | V7: 22 | W7: 23 | X7: 24 | Y7: 25 | Z7: 26
E8: 0 | F8: =1+E8 -> 1 | J8: =H8*I8 -> 0 | M8: =K8*L8 -> 0 | N8: =J8+M8 -> 0 | P8: =ROUNDUP(IF(N8="",0,N8/O8),2) -> #DIV/0! | S8: =Q8*R8 -> 0 | V8: =T8*U8 -> 0 | W8: =S8+V8 -> 0 | Y8: =ROUNDUP(W8/X8,2) -> #DIV/0! | Z8: =IF(G8+Y8+P8<0,"",G8+P8+Y8) -> #DIV/0!
E9: 0 | F9: =1+E9 -> 1 | J9: =H9*I9 -> 0 | M9: =K9*L9 -> 0 | N9: =J9+M9 -> 0 | P9: =ROUNDUP(IF(N9="",0,N9/O9),2) -> #DIV/0! | S9: =Q9*R9 -> 0 | V9: =T9*U9 -> 0 | W9: =S9+V9 -> 0 | Y9: =ROUNDUP(W9/X9,2) -> #DIV/0! | Z9: =IF(G9+Y9+P9<0,"",G9+P9+Y9) -> #DIV/0!
E10: 0 | F10: =1+E10 -> 1 | J10: =H10*I10 -> 0 | M10: =K10*L10 -> 0 | N10: =J10+M10 -> 0 | P10: =ROUNDUP(IF(N10="",0,N10/O10),2) -> #DIV/0! | S10: =Q10*R10 -> 0 | V10: =T10*U10 -> 0 | W10: =S10+V10 -> 0 | Y10: =ROUNDUP(W10/X10,2) -> #DIV/0! | Z10: =IF(G10+Y10+P10<0,"",G10+P10+Y10) -> #DIV/0!
E11: 0 | F11: =1+E11 -> 1 | J11: =H11*I11 -> 0 | M11: =K11*L11 -> 0 | N11: =J11+M11 -> 0 | P11: =ROUNDUP(IF(N11="",0,N11/O11),2) -> #DIV/0! | S11: =Q11*R11 -> 0 | V11: =T11*U11 -> 0 | W11: =S11+V11 -> 0 | Y11: =ROUNDUP(W11/X11,2) -> #DIV/0! | Z11: =IF(G11+Y11+P11<0,"",G11+P11+Y11) -> #DIV/0!
E12: 0 | F12: =1+E12 -> 1 | J12: =H12*I12 -> 0 | M12: =K12*L12 -> 0 | N12: =J12+M12 -> 0 | P12: =ROUNDUP(IF(N12="",0,N12/O12),2) -> #DIV/0! | S12: =Q12*R12 -> 0 | V12: =T12*U12 -> 0 | W12: =S12+V12 -> 0 | Y12: =ROUNDUP(W12/X12,2) -> #DIV/0! | Z12: =IF(G12+Y12+P12<0,"",G12+P12+Y12) -> #DIV/0!
E13: 0 | F13: =1+E13 -> 1 | J13: =H13*I13 -> 0 | M13: =K13*L13 -> 0 | N13: =J13+M13 -> 0 | P13: =ROUNDUP(IF(N13="",0,N13/O13),2) -> #DIV/0! | S13: =Q13*R13 -> 0 | V13: =T13*U13 -> 0 | W13: =S13+V13 -> 0 | Y13: =ROUNDUP(W13/X13,2) -> #DIV/0! | Z13: =IF(G13+Y13+P13<0,"",G13+P13+Y13) -> #DIV/0!
E14: 0 | F14: =1+E14 -> 1 | J14: =H14*I14 -> 0 | M14: =K14*L14 -> 0 | N14: =J14+M14 -> 0 | P14: =ROUNDUP(IF(N14="",0,N14/O14),2) -> #DIV/0! | S14: =Q14*R14 -> 0 | V14: =T14*U14 -> 0 | W14: =S14+V14 -> 0 | Y14: =ROUNDUP(W14/X14,2) -> #DIV/0! | Z14: =IF(G14+Y14+P14<0,"",G14+P14+Y14) -> #DIV/0!
E15: 0 | F15: =1+E15 -> 1 | J15: =H15*I15 -> 0 | M15: =K15*L15 -> 0 | N15: =J15+M15 -> 0 | P15: =ROUNDUP(IF(N15="",0,N15/O15),2) -> #DIV/0! | S15: =Q15*R15 -> 0 | V15: =T15*U15 -> 0 | W15: =S15+V15 -> 0 | Y15: =ROUNDUP(W15/X15,2) -> #DIV/0! | Z15: =IF(G15+Y15+P15<0,"",G15+P15+Y15) -> #DIV/0!
E16: 0 | F16: =1+E16 -> 1 | J16: =H16*I16 -> 0 | M16: =K16*L16 -> 0 | N16: =J16+M16 -> 0 | P16: =ROUNDUP(IF(N16="",0,N16/O16),2) -> #DIV/0! | S16: =Q16*R16 -> 0 | V16: =T16*U16 -> 0 | W16: =S16+V16 -> 0 | Y16: =ROUNDUP(W16/X16,2) -> #DIV/0! | Z16: =IF(G16+Y16+P16<0,"",G16+P16+Y16) -> #DIV/0!
E17: 0 | F17: =1+E17 -> 1 | J17: =H17*I17 -> 0 | M17: =K17*L17 -> 0 | N17: =J17+M17 -> 0 | P17: =ROUNDUP(IF(N17="",0,N17/O17),2) -> #DIV/0! | S17: =Q17*R17 -> 0 | V17: =T17*U17 -> 0 | W17: =S17+V17 -> 0 | Y17: =ROUNDUP(W17/X17,2) -> #DIV/0! | Z17: =IF(G17+Y17+P17<0,"",G17+P17+Y17) -> #DIV/0!
E18: 0 | F18: =1+E18 -> 1 | J18: =H18*I18 -> 0 | M18: =K18*L18 -> 0 | N18: =J18+M18 -> 0 | P18: =ROUNDUP(IF(N18="",0,N18/O18),2) -> #DIV/0! | S18: =Q18*R18 -> 0 | V18: =T18*U18 -> 0 | W18: =S18+V18 -> 0 | Y18: =ROUNDUP(W18/X18,2) -> #DIV/0! | Z18: =IF(G18+Y18+P18<0,"",G18+P18+Y18) -> #DIV/0!
E19: 0 | F19: =1+E19 -> 1 | J19: =H19*I19 -> 0 | M19: =K19*L19 -> 0 | N19: =J19+M19 -> 0 | P19: =ROUNDUP(IF(N19="",0,N19/O19),2) -> #DIV/0! | S19: =Q19*R19 -> 0 | V19: =T19*U19 -> 0 | W19: =S19+V19 -> 0 | Y19: =ROUNDUP(W19/X19,2) -> #DIV/0! | Z19: =IF(G19+Y19+P19<0,"",G19+P19+Y19) -> #DIV/0!
... E45: 0 | F45: =1+E45 -> 1 | J45: =H45*I45 -> 0 | M45: =K45*L45 -> 0 | N45: =J45+M45 -> 0 | P45: =ROUNDUP(IF(N45="",0,N45/O45),2) -> #DIV/0! | S45: =Q45*R45 -> 0 | V45: =T45*U45 -> 0 | W45: =S45+V45 -> 0 | Y45: =ROUNDUP(W45/X45,2) -> #DIV/0! | Z45: =IF(G45+Y45+P45<0,"",G45+P45+Y45) -> #DIV/0!
E46: 0 | F46: =1+E46 -> 1

Sheet SOUS DETAIL INTERMEDIAIRE COFFR
A1: Chantier : | B1: ='(C.H.M) MAIN D''OEUVRE'!C2 -> 1 | F1: Date | G1: =TODAY() -> 46093
A2: Désignation de l'ouvrage :
A3: Nombre de pièces à fabriquer :
A4: Nombre de m² à coffrer :
A5: Fabrication du moule
A7: Libellé | B7: Unité | C7: Quantité | D7: Prix Unitaire | E7: Déboursé
E8: Matériaux | F8: M.O | G8: Machine
A9: 1 - MATERIAUX
E10: =D10*C10 -> 0
A17: 2 - MAIN D'OEUVRE | B17: H | F17: =C17*D17 -> 0
A19: 3 - MATERIEL | B19: U | G19: =D19 -> 0
A21: RESULTATS UNITAIRES | E21: =SUM(E9:E14) -> 0 | F21: =F17 -> 0 | G21: =G19 -> 0
A22: PRIX DE MISE EN OEUVRE DU MOULE | G22: =SUM(E21,F21,G21) -> 0
A23: PRIX DE FABRICATION DE L'ENSEMBLE DES MOULE | G23: =G22*D3 -> 0
A24: AMORTISSEMENT DU MOULE PAR M² COFFRÉ | G24: =ROUND(G23/D4,2) -> #DIV/0!
A25: Mise en œuvre
A27: Libellé | B27: Unité | C27: Quantité | D27: Prix Unitaire | E27: Déboursé
E28: Matériaux | F28: M.O | G28: Matériel
A29: 1 - MATERIAUX
E30: =C30*D30 -> 0
A33: 2 - MAIN D'OEUVRE | B33: H | F33: =C33*D33 -> 0
A35: 3 - MATERIEL | B35: U | G35: =D35 -> 0
A37: RESULTATS UNITAIRES | E37: =E30 -> 0 | F37: =F31 -> 0 | G37: =G36 -> 0
A38: PRIX DE MISE EN OEUVRE DU MOULE | G38: =E36+F36+G36 -> 0
A39: PRIX DE MISE EN OEUVRE AU M² COFFRE | G39: =E37+F37+G37 -> 0
A40: DEBOURSE SEC UNITAIRE AU M² DE COFFRAGE | G40: =G39+G24 -> #DIV/0!

Sheet SOUS DETAIL INTERMEDIAIRE ACIER
A1: Chantier : | B1: ='(C.H.M) MAIN D''OEUVRE'!C2 -> 1 | F1: Date | G1: =TODAY() -> 46093
A3: ACIERS :
A4: Fournitures | B4: U | C4: Perte % | D4: Quantité | E4: Prix unitaire | F4: Total | G4: Total Gén.
A5: Aciers : | B5: T | C5: 0.06 | D5: =1+C5 -> 1.06 | E5: 792 | F5: =ROUND(D5*E5,2) -> 839.52
A6: Ligatures : | B6: T | D6: 0.015 | E6: 1395 | F6: =ROUND(D6*E6,2) -> 20.93
E8: Total des fournitures | G8: =SUM(F5:F6) -> 860.45
A9: Main d'œuvre | B9: H | D9: 60 | E9: 16.5 | F9: =ROUND(D9*E9,2) -> 990
A10: Amortissement | B10: U | D10: 1 | E10: 13 | F10: =ROUND(D10*E10,2) -> 13
E11: Total M.O + amortissement | G11: =SUM(F9:F10) -> 1003
E12: PRIX UNITAIRE à la Tonne | G12: =G8+G11 -> 1863.45
E13: PRIX UNITAIRE au KG | G13: =ROUND(G12/1000,2) -> 1.86
A18: ACIERS :
A19: Fournitures | B19: U | C19: Perte % | D19: Quantité | E19: Prix unitaire | F19: Total | G19: Total Gén.
A20: Aciers : | B20: T | F20: =ROUND(D20*E20,2) -> 0
A21: Ligatures : | B21: T | F21: =ROUND(D21*E21,2) -> 0
E23: Total des fournitures | G23: =SUM(F20:F21) -> 0
A24: Main d'œuvre | B24: H | F24: =ROUND(D24*E24,2) -> 0
A25: Amortissement | B25: U | F25: =ROUND(D25*E25,2) -> 0
E26: Total M.O + amortissement | G26: =SUM(F24:F25) -> 0
E27: PRIX UNITAIRE à la Tonne | G27: =G23+G26 -> 0
E28: PRIX UNITAIRE au KG | G28: =ROUND(G27/1000,2) -> 0

Sheet SOUS DETAIL INTERMEDIAIRE BÉTON
A1: Chantier : | B1: ='(C.H.M) MAIN D''OEUVRE'!C2 -> 1 | G1: Date : | H1: =TODAY() -> 46093
A4: Béton n° 1 dosé à :250 kg/m3
A5: Fournitures | B5: U | C5: Perte % | D5: Quantité | E5: Total Quantité | F5: Prix unitaire | G5: Total | H5: Total Gén.
A6: Sable 0/6 | B6: T | C6: 0 | D6: 0 | E6: =SUM(D6+C6*D6) -> 0 | F6: 0 | G6: =ROUND(E6*F6,2) -> 0
A7: Gravier 5/15 | B7: T | C7: 0 | D7: 0 | E7: =SUM(D7+C7*D7) -> 0 | F7: 0 | G7: =ROUND(E7*F7,2) -> 0
A8: cailloux | B8: T | C8: 0 | D8: 0 | E8: =SUM(D8+C8*D8) -> 0 | F8: 0 | G8: =ROUND(E8*F8,2) -> 0
A9: Ciment CPJ | B9: T | C9: 0 | D9: 0 | E9: =SUM(D9+C9*D9) -> 0 | F9: 0 | G9: =ROUND(E9*F9,2) -> 0
E10: Total des fournitures | H10: =SUM(G6:G9) -> 0
A11: Main d'œuvre | B11: H | D11: 0 | F11: 16.5 | G11: =ROUND(D11*F11,2) -> 0
A12: Amortissement | B12: U | D12: 1 | F12: 0 | G12: =ROUND(D12*F12,2) -> 0
E13: Total M.O + amortissement | H13: =SUM(G11:G12) -> 0
E14: PRIX UNITAIRE au m3 | H14: =SUM(H13,H10) -> 0
A16: Béton n° 2 dosé à :300 kg/m3
A17: Fournitures | B17: U | C17: Perte % | D17: Quantité | E17: Total Quantité | F17: Prix unitaire | G17: Total | H17: Total Gén.
A18: Sable 0/6 | B18: T | C18: 0 | D18: 0 | E18: =SUM(D18+C18*D18) -> 0 | F18: 0 | G18: =ROUND(E18*F18,2) -> 0
A19: Gravier 5/15 | B19: T | C19: 0 | D19: 0 | E19: =SUM(D19+C19*D19) -> 0 | F19: 0 | G19: =ROUND(E19*F19,2) -> 0
A20: cailloux | B20: T | C20: 0 | D20: 0 | E20: =SUM(D20+C20*D20) -> 0 | F20: 0 | G20: =ROUND(E20*F20,2) -> 0
A21: Ciment CPJ | B21: T | C21: 0 | D21: 0 | E21: =SUM(D21+C21*D21) -> 0 | F21: 0 | G21: =ROUND(E21*F21,2) -> 0
E22: Total des fournitures | H22: =SUM(G18:G21) -> 0
A23: Main d'œuvre | B23: H | D23: 0 | F23: 16.5 | G23: =ROUND(D23*F23,2) -> 0
A24: Amortissement | B24: U | D24: 1 | F24: 0 | G24: =ROUND(D24*F24,2) -> 0
E25: Total M.O + amortissement | H25: =SUM(G23:G24) -> 0
E26: PRIX UNITAIRE au m3 | H26: =SUM(H25,H22) -> 0
A28: Béton n° 3 dosé à :350 kg/m3
A29: Fournitures | B29: U | C29: Perte % | D29: Quantité | E29: Total Quantité | F29: Prix unitaire | G29: Total | H29: Total Gén.
A30: Sable 0/6 | B30: T | C30: 0 | D30: 0 | E30: =SUM(D30+C30*D30) -> 0 | F30: 0 | G30: =ROUND(E30*F30,2) -> 0
A31: Gravier 5/15 | B31: T | C31: 0 | D31: 0 | E31: =SUM(D31+C31*D31) -> 0 | F31: 0 | G31: =ROUND(E31*F31,2) -> 0
A32: cailloux | B32: T | C32: 0 | D32: 0 | E32: =SUM(D32+C32*D32) -> 0 | F32: 0 | G32: =ROUND(E32*F32,2) -> 0
A33: Ciment CPJ | B33: T | C33: 0 | D33: 0 | E33: =SUM(D33+C33*D33) -> 0 | F33: 0 | G33: =ROUND(E33*F33,2) -> 0
E34: Total des fournitures | H34: =SUM(G30:G33) -> 0
A35: Main d'œuvre | B35: H | D35: 0 | F35: 16.5 | G35: =ROUND(D35*F35,2) -> 0
A36: Amortissement | B36: U | D36: 1 | F36: 0 | G36: =ROUND(D36*F36,2) -> 0
E37: Total M.O + amortissement | H37: =SUM(G35:G36) -> 0
E38: PRIX UNITAIRE au m3 | H38: =SUM(H37,H34) -> 0

Sheet SOUS DETAIL INTERMEDIAIRE MORTI
A1: Chantier : | B1: Mairie de Sainte-Croix | G1: Date : | H1: =TODAY() -> 46093
A3: Mortier 150 kg
A4: Fournitures | B4: U | C4: Perte % | D4: Quantité | E4: Total Quantité | F4: Prix unitaire | G4: Total | H4: Total Gén.
A5: Sable | B5: m³ | C5: 0.1 | D5: 1.2 | E5: =SUM(D5+C5*D5) -> 1.32 | F5: 16.5 | G5: =F5*E5 -> 21.78
A6: Ciment | B6: kg | C6: 0.1 | D6: 150 | E6: =SUM(D6+C6*D6) -> 165 | F6: 0.42 | G6: =F6*E6 -> 69.3
A7: Chaux | B7: kg | C7: 0.1 | D7: 150 | E7: =SUM(D7+C7*D7) -> 165 | F7: 0.38 | G7: =F7*E7 -> 62.7
C8: 0 | D8: 0 | E8: =SUM(D8+C8*D8) -> 0 | F8: 0 | G8: =F8*E8 -> 0
F9: Total des fournitures | H9: =SUM(G5:G8) -> 153.78
A10: Main d'œuvre | B10: H | D10: 1.58 | F10: 24.3 | G10: =ROUND(D10*F10,2) -> 38.39
A11: Amortissement | B11: U | D11: 0 | F11: 0 | G11: =ROUND(D11*F11,2) -> 0
E12: Total M.O + amortissement | H12: =SUM(G10:G11) -> 38.39
E13: PRIX UNITAIRE au m3 | H13: =SUM(H12,H9) -> 192.17
A18: Mortier 300 kg
A19: Fournitures | B19: U | C19: Perte % | D19: Quantité | E19: Total Quantité | F19: Prix unitaire | G19: Total | H19: Total Gén.
A20: Sable | B20: m³ | C20: 0.1 | D20: 1.2 | E20: =SUM(D20+C20*D20) -> 1.32 | F20: 16.5 | G20: =F20*E20 -> 21.78
A21: Ciment | B21: kg | C21: 0.1 | D21: 300 | E21: =SUM(D21+C21*D21) -> 330 | F21: 0.42 | G21: =F21*E21 -> 138.6
A22: Chaux | B22: kg | C22: 0.1 | D22: 300 | E22: =SUM(D22+C22*D22) -> 330 | F22: 0.38 | G22: =F22*E22 -> 125.4
C23: 0 | D23: 0 | E23: =SUM(D23+C23*D23) -> 0 | F23: 0 | G23: =F23*E23 -> 0
F24: Total des fournitures | H24: =SUM(G20:G23) -> 285.78
A25: Main d'œuvre | B25: H | D25: 1.58 | F25: 24.3 | G25: =ROUND(D25*F25,2) -> 38.39
A26: Amortissement | B26: U | D26: 0 | F26: 0 | G26: =ROUND(D26*F26,2) -> 0
E27: Total M.O + amortissement | H27: =SUM(G25:G26) -> 38.39
E28: PRIX UNITAIRE au m3 | H28: =SUM(H27,H24) -> 324.17

Sheet SOUS DETAIL UNITAIRE
A2: Titre de l'ouvrage : | B2: Doublage Optima 13 + 140 mm | E2: Date : | F2: =TODAY() -> 46093
E3: Unité : | F3: m²
A5: Fournitures | B5: U | C5: Perte % | D5: Quantité | E5: Total Quantité | F5: P.U. | G5: Total
A6: Plaque de plâtre BA13 | B6: m² | C6: 0 | D6: 1.05 | E6: =SUM(D6+C6*D6) -> 1.05 | F6: =N6 -> 3.2 | G6: =F6*E6 -> 3.36 | I6: BA13 | J6: 1,20 x 2,50 = | K6: =1.2*2.5 -> 3 | M6: 9,60 / 3 m² = | N6: =9.6/3 -> 3.2 | O6: €/m²
A7: Isolant GR32 ép. 140mm | B7: m² | C7: 0 | D7: 1.05 | E7: =SUM(D7+C7*D7) -> 1.05 | F7: =N7 -> 3.8461538 | G7: =F7*E7 -> 4.0384615 | I7: Isolant 140mm | J7: 1,20 x 5,20 = | K7: =1.2*5.2 -> 6.24 | M7: 24 / 6,24 m² = | N7: =24/6.24 -> 3.8461538 | O7: €/m²
A8: Lisse basse et haute (Rail 4m) | B8: ml | C8: 0 | D8: 0.9 | E8: =SUM(D8+C8*D8) -> 0.9 | F8: =K8 -> 0.8 | G8: =F8*E8 -> 0.72 | I8: Lisse | J8: 3,20 / 4 = | K8: =3.2/4 -> 0.8
A9: Membrane d'étanchéité | B9: m² | C9: 0 | D9: 1.1 | E9: =SUM(D9+C9*D9) -> 1.1 | F9: 1.8 | G9: =F9*E9 -> 1.98
A10: Fourrure 3m | B10: ml | C10: 0 | D10: 1.83 | E10: =SUM(D10+C10*D10) -> 1.83 | F10: =K10 -> 1.1 | G10: =F10*E10 -> 2.013 | I10: Fourrure | J10: 3,30 / 3 = | K10: =3.3/3 -> 1.1
A11: Vis TF 45mm | B11: U | C11: 0 | D11: 12 | E11: =SUM(D11+C11*D11) -> 12 | F11: =K11 -> 0.012 | G11: =F11*E11 -> 0.144 | I11: Vis | J11: 12 / 1000 = | K11: =12/1000 -> 0.012
A12: Appui intermédiaire Optima | B12: U | C12: 0 | D12: 1 | E12: =SUM(D12+C12*D12) -> 1 | F12: =K12 -> 0.76 | G12: =F12*E12 -> 0.76 | I12: Appui | J12: 38 / 50 = | K12: =38/50 -> 0.76
A13: Bande à joint | B13: ml | C13: 0 | D13: 1.4 | E13: =SUM(D13+C13*D13) -> 1.4 | F13: =K13 -> 0.1 | G13: =F13*E13 -> 0.14 | I13: Bande à joint | J13: 15 / 150 = | K13: =15/150 -> 0.1
A14: Adhésif type Vario | B14: ml | C14: 0 | D14: 1.6 | E14: =SUM(D14+C14*D14) -> 1.6 | F14: =K14 -> 0.24 | G14: =F14*E14 -> 0.384 | I14: Adhésif | J14: 12 / 50 = | K14: =12/50 -> 0.24
A15: Enduit pour joints | B15: kg | C15: 0 | D15: 0.35 | E15: =SUM(D15+C15*D15) -> 0.35 | F15: =K15 -> 0.8 | G15: =F15*E15 -> 0.28 | I15: Enduit | J15: 16 / 20 = | K15: =16/20 -> 0.8
A16: Eclisse (rallonge) | B16: U | C16: 0 | D16: 1 | E16: =SUM(D16+C16*D16) -> 1 | F16: =K16 -> 1 | G16: =F16*E16 -> 1 | I16: Eclisse | J16: 25 / 25 = | K16: =25/25 -> 1
C17: 0 | D17: 0 | E17: =SUM(D17+C17*D17) -> 0 | F17: 0 | G17: =F17*E17 -> 0
E19: Total fournitures | G19: =SUM(G6:G17) -> 14.819462
A21: Location matériel | B21: U | C21: Quantité | E21: P.U. | F21: Total
C22: 0 | E22: 0 | F22: =E22*C22 -> 0
C23: 0 | E23: 0 | F23: =E23*C23 -> 0
C24: 0 | E24: 0 | F24: =E24*C24 -> 0
C25: 0 | E25: 0 | F25: =E25*C25 -> 0
E27: Total matériel | G27: =SUM(F22:F25) -> 0
A29: Main d'œuvre | C29: Heures | E29: P.M.H. | F29: Total
A30: Main d'œuvre | C30: 0.9 | E30: 25.8 | F30: =E30*C30 -> 23.22
C31: 0 | E31: 0 | F31: =E31*C31 -> 0
C32: 0 | E32: 0 | F32: =E32*C32 -> 0
C33: 0 | E33: 0 | F33: =E33*C33 -> 0
E35: Total main d'œuvre | G35: =SUM(F30:F33) -> 23.22
D37: Total déboursé sec unitaire | G37: =G19+G27+G35 -> 38.039462
A39: Coefficcient de vente | D39: =G280 -> 1.375 | G39: =G37*D39 -> 52.30426
A45: Titre de l'ouvrage : | B45: Faux plafond ossature métallique | E45: Date : | F45: =TODAY() -> 46093
E46: Unité : | F46: m²
A48: Fournitures | B48: U | C48: Perte % | D48: Quantité | E48: Total Quantité | F48: P.U. | G48: Total
A49: Plaque de plâtre BA13 | B49: m² | C49: 0 | D49: 1.05 | E49: =SUM(D49+C49*D49) -> 1.05 | F49: =N6 -> 3.2 | G49: =F49*E49 -> 3.36
A50: Lisse périphérique (Rail 4m) | B50: ml | C50: 0 | D50: 0.3 | E50: =SUM(D50+C50*D50) -> 0.3 | F50: 1 | G50: =F50*E50 -> 0.3
A51: Fourrure 3m | B51: ml | C51: 0 | D51: 2 | E51: =SUM(D51+C51*D51) -> 2 | F51: 1.1 | G51: =F51*E51 -> 2.2
A52: Suspente | B52: U | C52: 0 | D52: 1.8 | E52: =SUM(D52+C52*D52) -> 1.8 | F52: =K52 -> 0.152 | G52: =F52*E52 -> 0.2736 | I52: Suspente | J52: 38 / 250 = | K52: =38/250 -> 0.152
A53: Vis TF 45mm | B53: U | C53: 0 | D53: 12 | E53: =SUM(D53+C53*D53) -> 12 | F53: 0.012 | G53: =F53*E53 -> 0.144
A54: Bande à joint | B54: ml | C54: 0 | D54: 1.6 | E54: =SUM(D54+C54*D54) -> 1.6 | F54: 0.1 | G54: =F54*E54 -> 0.16
A55: Enduit pour joints | B55: kg | C55: 0 | D55: 0.35 | E55: =SUM(D55+C55*D55) -> 0.35 | F55: 0.8 | G55: =F55*E55 -> 0.28
...

Sheet CALCUL DES PRIX 
A1: Chantier : | C1: ='(C.H.M) MAIN D''OEUVRE'!C2 -> 1 | N1: Date : | P1: =TODAY() -> 46093
A2: Coût horaire moyen (A) = | C2: 0 | M2: Coef. de vente (B) = | P2: =L55 -> 1
A3: N° Code | B3: Désignation des ouvrages | C3: U | D3: Quantité | E3: Chantier | G3: Fabrication | I3: Dépense Fournitures | J3: Dépense Matériel | K3: Déboursé Sec unit | L3: Déboursé sec Total | M3: Total Fournitures | N3: Total Matériel | O3: Total des heures | P3: PRIX DE VENTE
E4: temps unit | F4: Dépense M.O. unit | G4: temps unit | H4: Dépense M.O. unit | P4: unitaire | Q4: TOTAL
D5: 1 | E5: 2 | F5: 3 = 2xCHM | G5: 4 | H5: 5 = 4xCHM | I5: 6 = SDU | J5: 7 = SDU | K5: 8 = 3+5+6+7 | L5: 9 = 1x8 | M5: 10 = 1x6 | N5: 11 = 6x7 | O5: 12 = 1x(2+4) | P5: 13 = 8x(coef) | Q5: 14 = 1 x 13
A6: 01 | E6: 0 | F6: =ROUND(E6*$C$2,2) -> 0 | H6: =ROUND(G6*$C$2,2) -> 0 | K6: =F6+H6+I6+J6 -> 0 | L6: =ROUND(K6*D6,2) -> 0 | M6: =ROUND(I6*D6,2) -> 0 | N6: =ROUND(J6*D6,2) -> 0 | O6: =ROUND(D6*(E6+G6),2) -> 0 | P6: =ROUND(K6*$P$2,2) -> 0 | Q6: =ROUND(P6*D6,2) -> 0
A7: 02 | E7: 0 | F7: =ROUND(E7*$C$2,2) -> 0 | H7: =ROUND(G7*$C$2,2) -> 0 | K7: =F7+H7+I7+J7 -> 0 | L7: =ROUND(K7*D7,2) -> 0 | M7: =ROUND(I7*D7,2) -> 0 | N7: =ROUND(J7*D7,2) -> 0 | O7: =ROUND(D7*(E7+G7),2) -> 0 | P7: =ROUND(K7*$P$2,2) -> 0 | Q7: =ROUND(P7*D7,2) -> 0
A8: 03 | E8: 0 | F8: =ROUND(E8*$C$2,2) -> 0 | H8: =ROUND(G8*$C$2,2) -> 0 | K8: =F8+H8+I8+J8 -> 0 | L8: =ROUND(K8*D8,2) -> 0 | M8: =ROUND(I8*D8,2) -> 0 | N8: =ROUND(J8*D8,2) -> 0 | O8: =ROUND(D8*(E8+G8),2) -> 0 | P8: =ROUND(K8*$P$2,2) -> 0 | Q8: =ROUND(P8*D8,2) -> 0
A9: 04 | E9: 0 | F9: =ROUND(E9*$C$2,2) -> 0 | H9: =ROUND(G9*$C$2,2) -> 0 | K9: =F9+H9+I9+J9 -> 0 | L9: =ROUND(K9*D9,2) -> 0 | M9: =ROUND(I9*D9,2) -> 0 | N9: =ROUND(J9*D9,2) -> 0 | O9: =ROUND(D9*(E9+G9),2) -> 0 | P9: =ROUND(K9*$P$2,2) -> 0 | Q9: =ROUND(P9*D9,2) -> 0
A10: 05 | E10: 0 | F10: =ROUND(E10*$C$2,2) -> 0 | H10: =ROUND(G10*$C$2,2) -> 0 | K10: =F10+H10+I10+J10 -> 0 | L10: =ROUND(K10*D10,2) -> 0 | M10: =ROUND(I10*D10,2) -> 0 | N10: =ROUND(J10*D10,2) -> 0 | O10: =ROUND(D10*(E10+G10),2) -> 0 | P10: =ROUND(K10*$P$2,2) -> 0 | Q10: =ROUND(P10*D10,2) -> 0
A11: 06 | E11: 0 | F11: =ROUND(E11*$C$2,2) -> 0 | H11: =ROUND(G11*$C$2,2) -> 0 | K11: =F11+H11+I11+J11 -> 0 | L11: =ROUND(K11*D11,2) -> 0 | M11: =ROUND(I11*D11,2) -> 0 | N11: =ROUND(J11*D11,2) -> 0 | O11: =ROUND(D11*(E11+G11),2) -> 0 | P11: =ROUND(K11*$P$2,2) -> 0 | Q11: =ROUND(P11*D11,2) -> 0
A12: 07 | E12: 0 | F12: =ROUND(E12*$C$2,2) -> 0 | H12: =ROUND(G12*$C$2,2) -> 0 | K12: =F12+H12+I12+J12 -> 0 | L12: =ROUND(K12*D12,2) -> 0 | M12: =ROUND(I12*D12,2) -> 0 | N12: =ROUND(J12*D12,2) -> 0 | O12: =ROUND(D12*(E12+G12),2) -> 0 | P12: =ROUND(K12*$P$2,2) -> 0 | Q12: =ROUND(P12*D12,2) -> 0
A13: 08 | E13: 0 | F13: =ROUND(E13*$C$2,2) -> 0 | H13: =ROUND(G13*$C$2,2) -> 0 | K13: =F13+H13+I13+J13 -> 0 | L13: =ROUND(K13*D13,2) -> 0 | M13: =ROUND(I13*D13,2) -> 0 | N13: =ROUND(J13*D13,2) -> 0 | O13: =ROUND(D13*(E13+G13),2) -> 0 | P13: =ROUND(K13*$P$2,2) -> 0 | Q13: =ROUND(P13*D13,2) -> 0
A14: 09 | E14: 0 | F14: =ROUND(E14*$C$2,2) -> 0 | H14: =ROUND(G14*$C$2,2) -> 0 | K14: =F14+H14+I14+J14 -> 0 | L14: =ROUND(K14*D14,2) -> 0 | M14: =ROUND(I14*D14,2) -> 0 | N14: =ROUND(J14*D14,2) -> 0 | O14: =ROUND(D14*(E14+G14),2) -> 0 | P14: =ROUND(K14*$P$2,2) -> 0 | Q14: =ROUND(P14*D14,2) -> 0
A15: 10 | E15: 0 | F15: =ROUND(E15*$C$2,2) -> 0 | H15: =ROUND(G15*$C$2,2) -> 0 | K15: =F15+H15+I15+J15 -> 0 | L15: =ROUND(K15*D15,2) -> 0 | M15: =ROUND(I15*D15,2) -> 0 | N15: =ROUND(J15*D15,2) -> 0 | O15: =ROUND(D15*(E15+G15),2) -> 0 | P15: =ROUND(K15*$P$2,2) -> 0 | Q15: =ROUND(P15*D15,2) -> 0
A16: 11 | E16: 0 | F16: =ROUND(E16*$C$2,2) -> 0 | H16: =ROUND(G16*$C$2,2) -> 0 | K16: =F16+H16+I16+J16 -> 0 | L16: =ROUND(K16*D16,2) -> 0 | M16: =ROUND(I16*D16,2) -> 0 | N16: =ROUND(J16*D16,2) -> 0 | O16: =ROUND(D16*(E16+G16),2) -> 0 | P16: =ROUND(K16*$P$2,2) -> 0 | Q16: =ROUND(P16*D16,2) -> 0
A17: 12 | E17: 0 | F17: =ROUND(E17*$C$2,2) -> 0 | H17: =ROUND(G17*$C$2,2) -> 0 | K17: =F17+H17+I17+J17 -> 0 | L17: =ROUND(K17*D17,2) -> 0 | M17: =ROUND(I17*D17,2) -> 0 | N17: =ROUND(J17*D17,2) -> 0 | O17: =ROUND(D17*(E17+G17),2) -> 0 | P17: =ROUND(K17*$P$2,2) -> 0 | Q17: =ROUND(P17*D17,2) -> 0
... A25: 20 | E25: 0 | F25: =ROUND(E25*$C$2,2) -> 0 | H25: =ROUND(G25*$C$2,2) -> 0 | K25: =F25+H25+I25+J25 -> 0 | L25: =ROUND(K25*D25,2) -> 0 | M25: =ROUND(I25*D25,2) -> 0 | N25: =ROUND(J25*D25,2) -> 0 | O25: =ROUND(D25*(E25+G25),2) -> 0 | P25: =ROUND(K25*$P$2,2) -> 0 | Q25: =ROUND(P25*D25,2) -> 0
A26: 21 | E26: 0 | F26: =ROUND(E26*$C$2,2) -> 0 | H26: =ROUND(G26*$C$2,2) -> 0 | K26: =F26+H26+I26+J26 -> 0 | L26: =ROUND(K26*D26,2) -> 0 | M26: =ROUND(I26*D26,2) -> 0 | N26: =ROUND(J26*D26,2) -> 0 | O26: =ROUND(D26*(E26+G26),2) -> 0 | P26: =ROUND(K26*$P$2,2) -> 0 | Q26: =ROUND(P26*D26,2) -> 0
A27: 22 | E27: 0 | F27: =ROUND(E27*$C$2,2) -> 0 | H27: =ROUND(G27*$C$2,2) -> 0 | K27: =F27+H27+I27+J27 -> 0 | L27: =ROUND(K27*D27,2) -> 0 | M27: =ROUND(I27*D27,2) -> 0 | N27: =ROUND(J27*D27,2) -> 0 | O27: =ROUND(D27*(E27+G27),2) -> 0 | P27: =ROUND(K27*$P$2,2) -> 0 | Q27: =ROUND(P27*D27,2) -> 0
A28: 23 | E28: 0 | F28: =ROUND(E28*$C$2,2) -> 0 | H28: =ROUND(G28*$C$2,2) -> 0 | K28: =F28+H28+I28+J28 -> 0 | L28: =ROUND(K28*D28,2) -> 0 | M28: =ROUND(I28*D28,2) -> 0 | N28: =ROUND(J28*D28,2) -> 0 | O28: =ROUND(D28*(E28+G28),2) -> 0 | P28: =ROUND(K28*$P$2,2) -> 0 | Q28: =ROUND(P28*D28,2) -> 0
A29: 24 | E29: 0 | F29: =ROUND(E29*$C$2,2) -> 0 | H29: =ROUND(G29*$C$2,2) -> 0 | K29: =F29+H29+I29+J29 -> 0 | L29: =ROUND(K29*D29,2) -> 0 | M29: =ROUND(I29*D29,2) -> 0 | N29: =ROUND(J29*D29,2) -> 0 | O29: =ROUND(D29*(E29+G29),2) -> 0 | P29: =ROUND(K29*$P$2,2) -> 0 | Q29: =ROUND(P29*D29,2) -> 0
A30: 25 | E30: 0 | F30: =ROUND(E30*$C$2,2) -> 0 | H30: =ROUND(G30*$C$2,2) -> 0 | K30: =F30+H30+I30+J30 -> 0 | L30: =ROUND(K30*D30,2) -> 0 | M30: =ROUND(I30*D30,2) -> 0 | N30: =ROUND(J30*D30,2) -> 0 | O30: =ROUND(D30*(E30+G30),2) -> 0 | P30: =ROUND(K30*$P$2,2) -> 0 | Q30: =ROUND(P30*D30,2) -> 0
A31: 26 | E31: 0 | F31: =ROUND(E31*$C$2,2) -> 0 | H31: =ROUND(G31*$C$2,2) -> 0 | K31: =F31+H31+I31+J31 -> 0 | L31: =ROUND(K31*D31,2) -> 0 | M31: =ROUND(I31*D31,2) -> 0 | N31: =ROUND(J31*D31,2) -> 0 | O31: =ROUND(D31*(E31+G31),2) -> 0 | P31: =ROUND(K31*$P$2,2) -> 0 | Q31: =ROUND(P31*D31,2) -> 0
A32: 27 | E32: 0 | F32: =ROUND(E32*$C$2,2) -> 0 | H32: =ROUND(G32*$C$2,2) -> 0 | K32: =F32+H32+I32+J32 -> 0 | L32: =ROUND(K32*D32,2) -> 0 | M32: =ROUND(I32*D32,2) -> 0 | N32: =ROUND(J32*D32,2) -> 0 | O32: =ROUND(D32*(E32+G32),2) -> 0 | P32: =ROUND(K32*$P$2,2) -> 0 | Q32: =ROUND(P32*D32,2) -> 0
A33: 28 | E33: 0 | F33: =ROUND(E33*$C$2,2) -> 0 | H33: =ROUND(G33*$C$2,2) -> 0 | K33: =F33+H33+I33+J33 -> 0 | L33: =ROUND(K33*D33,2) -> 0 | M33: =ROUND(I33*D33,2) -> 0 | N33: =ROUND(J33*D33,2) -> 0 | O33: =ROUND(D33*(E33+G33),2) -> 0 | P33: =ROUND(K33*$P$2,2) -> 0 | Q33: =ROUND(P33*D33,2) -> 0
A34: 29 | E34: 0 | F34: =ROUND(E34*$C$2,2) -> 0 | H34: =ROUND(G34*$C$2,2) -> 0 | K34: =F34+H34+I34+J34 -> 0 | L34: =ROUND(K34*D34,2) -> 0 | M34: =ROUND(I34*D34,2) -> 0 | N34: =ROUND(J34*D34,2) -> 0 | O34: =ROUND(D34*(E34+G34),2) -> 0 | P34: =ROUND(K34*$P$2,2) -> 0 | Q34: =ROUND(P34*D34,2) -> 0
A35: 30 | E35: 0 | F35: =ROUND(E35*$C$2,2) -> 0 | H35: =ROUND(G35*$C$2,2) -> 0 | K35: =F35+H35+I35+J35 -> 0 | L35: =ROUND(K35*D35,2) -> 0 | M35: =ROUND(I35*D35,2) -> 0 | N35: =ROUND(J35*D35,2) -> 0 | O35: =ROUND(D35*(E35+G35),2) -> 0 | P35: =ROUND(K35*$P$2,2) -> 0 | Q35: =ROUND(P35*D35,2) -> 0
A36: 31 | E36: 0 | F36: =ROUND(E36*$C$2,2) -> 0 | H36: =ROUND(G36*$C$2,2) -> 0 | K36: =F36+H36+I36+J36 -> 0 | L36: =ROUND(K36*D36,2) -> 0 | M36: =ROUND(I36*D36,2) -> 0 | N36: =ROUND(J36*D36,2) -> 0 | O36: =ROUND(D36*(E36+G36),2) -> 0 | P36: =ROUND(K36*$P$2,2) -> 0 | Q36: =ROUND(P36*D36,2) -> 0
A37: 32 | E37: 0 | F37: =ROUND(E37*$C$2,2) -> 0 | H37: =ROUND(G37*$C$2,2) -> 0 | K37: =F37+H37+I37+J37 -> 0 | L37: =ROUND(K37*D37,2) -> 0 | M37: =ROUND(I37*D37,2) -> 0 | N37: =ROUND(J37*D37,2) -> 0 | O37: =ROUND(D37*(E37+G37),2) -> 0 | P37: =ROUND(K37*$P$2,2) -> 0 | Q37: =ROUND(P37*D37,2) -> 0
K39: TOTAL = | L39: =SUM(L6:L38) -> 0 | M39: =SUM(M6:M38) -> 0 | N39: =SUM(N6:N38) -> 0 | O39: =SUM(O6:O38) -> 0 | Q39: =SUM(Q6:Q38) -> 0
F43: Détermination du coefficient de vente
E45: Libellé | L45: valeurs
E46: Déboursés secs | L46: 1
E47: Frais de chantier | K47: 0 | L47: =L46*K47 -> 0
E48: Déboursés Totaux | L48: =L46+L47 -> 1
E49: Frais généraux | K49: 0 | L49: =ROUND(L48*K49,2) -> 0
E50: Frais de marché | K50: 0 | L50: =ROUND(L48*K50,2) -> 0
E51: Prix de revient entreprise | L51: =SUM(L48:M50) -> 1
E52: Bénéfices et aléas | K52: 0 | L52: =ROUND(L51*K52,2) -> 0
...

Sheet DEVIS ESTIMATIF
A1: Projet : | B1: ='(C.H.M) MAIN D''OEUVRE'!C2 -> 1 | C1: Coefficient de règlement : | F1: 0 | G1: Date : | H1: =TODAY() -> 46093
A2: Code | B2: Désignation des ouvrages | C2: U | D2: Quantités | E2: Déboursés secs | G2: Prix de vente H.T.
E3: P.U. | F3: Montant 4 x 5 | G3: P.U. 5 x coef. | H3: Montant 4 x 7
A5: 1 | B5: 2 | C5: 3 | D5: 4 | E5: 5 | F5: 6 | G5: 7 | H5: 8
A6: 01 | F6: =ROUND(D6*E6,2) -> 0 | G6: =ROUND($F$1*E6,2) -> 0 | H6: =ROUND(D6*G6,2) -> 0
F7: =ROUND(D7*E7,2) -> 0 | G7: =ROUND($F$1*E7,2) -> 0 | H7: =ROUND(D7*G7,2) -> 0
F8: =ROUND(D8*E8,2) -> 0 | G8: =ROUND($F$1*E8,2) -> 0 | H8: =ROUND(D8*G8,2) -> 0
F9: =ROUND(D9*E9,2) -> 0 | G9: =ROUND($F$1*E9,2) -> 0 | H9: =ROUND(D9*G9,2) -> 0
F10: =ROUND(D10*E10,2) -> 0 | G10: =ROUND($F$1*E10,2) -> 0 | H10: =ROUND(D10*G10,2) -> 0
F11: =ROUND(D11*E11,2) -> 0 | G11: =ROUND($F$1*E11,2) -> 0 | H11: =ROUND(D11*G11,2) -> 0
F12: =ROUND(D12*E12,2) -> 0 | G12: =ROUND($F$1*E12,2) -> 0 | H12: =ROUND(D12*G12,2) -> 0
F13: =ROUND(D13*E13,2) -> 0 | G13: =ROUND($F$1*E13,2) -> 0 | H13: =ROUND(D13*G13,2) -> 0
F14: =ROUND(D14*E14,2) -> 0 | G14: =ROUND($F$1*E14,2) -> 0 | H14: =ROUND(D14*G14,2) -> 0
F15: =ROUND(D15*E15,2) -> 0 | G15: =ROUND($F$1*E15,2) -> 0 | H15: =ROUND(D15*G15,2) -> 0
F16: =ROUND(D16*E16,2) -> 0 | G16: =ROUND($F$1*E16,2) -> 0 | H16: =ROUND(D16*G16,2) -> 0
F17: =ROUND(D17*E17,2) -> 0 | G17: =ROUND($F$1*E17,2) -> 0 | H17: =ROUND(D17*G17,2) -> 0
F18: =ROUND(D18*E18,2) -> 0 | G18: =ROUND($F$1*E18,2) -> 0 | H18: =ROUND(D18*G18,2) -> 0
... F27: =ROUND(D27*E27,2) -> 0 | G27: =ROUND($F$1*E27,2) -> 0 | H27: =ROUND(D27*G27,2) -> 0
E28: Total D.S. | F28: =SUM(F6:F27) -> 0 | G28: Total D.T. | H28: =SUM(H6:H27) -> 0

Sheet Coef. Vente
A1: COEFFICIENT MULTIPLICATEUR
A3: Chantier : | C3: Date : | E3: =TODAY() -> 46093
A5: Libellé | C5: Valeurs | F5: Application
A6: Déboursés secs : | D6: % | E6: 1 | G6: 150000
A7: Frais de chantier : | C7: 0.1 | D7: =IF(F7="DS",C7,IF(F7="PV HT",C7/(1-$I$15),IF(F7="DT",C7/(1-$I$17),C7/(1-$I$19)))) -> 0.1 | E7: =ROUND(E6*C7,2) -> 0.1 | F7: DS | G7: =C7*G6 -> 15000 | I7: Somme % PV HT
A8: Déboursés Totaux : | E8: =SUM(E6:E7) -> 1.1 | G8: =E8*G6 -> 165000 | I8: =SUMIF(F9:F13,"=PV HT",C9:C13) -> 0.08 | M8: DS
A9: Frais généraux : | C9: 0.15 | D9: =IF(F9="DT",C9,IF(F9="PR",C9/(1-$I$12),C9/(1-$I$8))) -> 0.15 | E9: =E8*D9 -> 0.165 | F9: DT | G9: =G8*D9 -> 24750 | M9: DT | N9: PR
A10: Frais de marché : | C10: 0 | D10: =IF(F10="DT",C10,IF(F10="PR",C10/(1-$I$12),C10/(1-$I$8))) -> 0 | E10: =E8*D10 -> 0 | G10: =D10*G8 -> 0 | I10: Somme % PR | M10: PR | N10: PV HT
A11: Prorata : | C11: 0 | D11: =IF(F11="DT",C11,IF(F11="PR",C11/(1-$I$12),C11/(1-$I$8))) -> 0 | E11: =E9*D11 -> 0
A12: Prix de revient entreprise : | C12: 0 | E12: =E8+E9+E10 -> 1.265 | G12: =E12*G6 -> 189750 | I12: =SUMIF(F9:F10,"=PR",C9:C10) -> 0 | M12: PV HT
A13: Bénéfices et aléas : | C13: 0.08 | D13: =IF(F13="PR",C13,C13/(1-C13)) -> 0.086956522 | E13: =E12*D13 -> 0.11 | F13: PV HT | G13: =G12*D13 -> 16500
A14: Prix de vente HT : | C14: =E12+E13 -> 1.375 | G14: =G6*C14 -> 206250 | I14: Somme % PV HT 2 | J14: FC
I15: =SUMIF(F7:F13,"=PV HT",C7:C13) -> 0.08
A16: Coefficient de vente = P.V/D.S : | C16: =C14/E6 -> 1.375 | I16: Somme % DT 2
I17: =SUMIF(F7:F13,"=DT",C7:C13) -> 0.15
I18: Somme % PR 2
I19: =SUMIF(F7:F13,"=PR",C7:C13) -> 0

Sheet Feuille Vente
A2: Le Belloy | B2: FEUILLE DE VENTE
B3: Rédacteur
B4: Date: | C4: 0
B5: % sur travaux entreprise | C5: % sur travaux sous traités | D5: Montants travaux entreprise | E5: Montants travaux sous traités
A6: DEBOURSES SECS DS | D6: 0
A7: Frais de chantier
A8: en % des déboursés secs | D8: 0
A9: en valeur total estimée
A10: en déboursé en selon détail calcul FC
A11: Total F.C. | D11: =SUM(D8:D10) -> 0
A12: DEBOURSES TOTAUX DT | D12: =SUM(D6+D11) -> 0
A13: Frais généraux de structure
A14: en % des déboursés totaux | B14: 0 | D14: =D12*B14 -> 0
A15: en % du prix de vente H.T. | D15: =#REF!*B15 -> #REF!
A16: Total F.G. | D16: =SUM(D14:D15) -> #REF!
A17: Frais de marché
A18: en % du DT H.T. | B18: 0 | D18: =D12*B18 -> 0
A19: en valeur H.T.
A20: Total F.M. | D20: =SUM(D18:D19) -> 0
A21: PRIX DE REVIENT PR | D21: =D20+D16+D12 -> #REF!
A22: Bénéfices et aléas
A23: en % du prix de revient
A24: en % du prix de vente H.T. | B24: 0 | D24: =D21*B24 -> #REF!
A25: Total Bénéfice | D25: =SUM(D23:D24) -> #REF!
A26: PRIX DE VENTE HT | D26: =H21*D21 -> #REF!
A27: T.V.A. taux | B27: 0 | D27: =D26*B27 -> #REF!
A28: PRIX DE VENTE T.T.C. | D28: =D27+D26 -> #REF!
A29: PRIX DE VENTE TOTAL T.T.C.
A30: COEFFICIENTS DE VENTE HT | B30: =D26/D6 -> #REF!
A31: Travaux entreprise Kc
A32: Travaux sous traités K1
A33: MARGE BRUTE
A35: verification | B35: =D26/D6 -> #REF!
A37: prix de vente m3 de beton | B37: =120.25*B35 -> #REF!
A45: Le Belloy | B45: FEUILLE DE VENTE
B46: Rédacteur : RENARD Henri TSEC 4 22
B47: Date: | C47: P 37
B48: % sur travaux entreprise | C48: % sur travaux sous traités | D48: Montants travaux entreprise | E48: Montants travaux sous traités
A49: DEBOURSES SECS DS | D49: ='[4]Calculs des Prix DS'!J99 -> 0
A50: Frais de chantier
...

Sheet FEUILLE DE VENTE
A1: Chantier : | B1: ='(C.H.M) MAIN D''OEUVRE'!C2 -> 1 | D1: Date : | E1: =TODAY() -> 46093
B2: % sur travaux entreprise | C2: % sur travaux sous traités | D2: Montants travaux entreprise | E2: Montants travaux sous traités
A4: DEBOURSES SECS DS | D4: 0 | E4: 0 | F4: Montant travaux entreprise
A5: Frais de chantier | Q5: ENTREPRISE
A6: en % des déboursés secs | B6: =H8 -> 0 | C6: =H22 -> 0 | D6: =D4*H8 -> 0 | E6: =E4*C6 -> 0 | H6: % du D.S | J6: % du P.V H.T | L6: % du D.T | N6: % du P.R
A7: en valeur total estimée | Q7: FC : | R7: 0 | S7: % DS
A8: en déboursé en selon détail calcul FC | F8: Frais de chantier : | H8: =R7/100 -> 0 | Q8: FG : | R8: 0 | S8: % DT HT
A9: Total F.C. | D9: =SUM(D6:D8) -> 0 | E9: =E6 -> 0 | Q9: FM : | R9: 0 | S9: % DT HT
A10: DEBOURSES TOTAUX DT | D10: =D4+D9 -> 0 | E10: =E4+E9 -> 0 | F10: Frais généraux : | J10: =IF(S8="% pv ht",(R8/100),0) -> 0 | K10: =(100/(100-((J10+J12+J13+J14)*100)))*J10 -> 0 | L10: =IF(S8="% dt ht",(R8/100),0) -> 0 | Q10: PRORATA : | R10: 0 | S10: % DT HT
A11: Frais généraux de structure | Q11: BE : | R11: 0 | S11: % PV HT
A12: en % des déboursés totaux | B12: =IF(S8="% DT HT",L10,0) -> 0 | C12: =IF(S21="% DT HT",L24,IF(S21="% st ht",O24,0)) -> 0 | D12: =IF(S8="% DT HT",D10*B12,IF(S8="% PV HT",0)) -> 0 | E12: =IF(S21="% DT HT",E10*C12,IF(S21="% PV HT",0)) -> 0 | F12: Frais de marchés : | J12: =IF(S9="% pv ht",(R9/100),0) -> 0 | K12: =(100/(100-((J10+J12+J13+J14)*100)))*J12 -> 0 | L12: =IF(S9="% dt ht",(R9/100),0) -> 0
A13: en % du prix de vente H.T. | B13: =IF(S8="% PV HT",J10,0) -> 0 | C13: =IF(S21="% PV HT",J24,0) -> 0 | D13: =IF(S8="% DT HT","",IF(J10="","",(D10+D12+D19+D17)*K10)) | E13: =IF(S21="% DT HT","",IF(K24="","",(E10+E12+E19)*K24)) | F13: Prorata : | J13: =IF(S10="% pv ht",(R10/100),0) -> 0 | K13: =(100/(100-((J10+J12+J13+J14)*100)))*J13 -> 0 | L13: =IF(S10="% dt ht",(R10/100),0) -> 0
A14: Total F.G. | D14: =SUM(D12:D13) -> 0 | E14: =SUM(E12:E13) -> 0 | F14: Bénéfices et aléas : | J14: =IF(S11="% pv ht",(R11/100),0) -> 0 | K14: =(100/(100-((J14)*100))*J14) -> 0 | N14: =IF(S11="% PR HT",(R11/100),0) -> 0
A15: Frais de marché
A16: en % du prix de vente HT | B16: =IF(S9="% PV HT",J12,0) -> 0 | C16: =IF(S22="% PV HT",J26,0) -> 0 | D16: =IF(J12="","",(D10+D12+D19+D17)*K12) -> 0 | E16: =IF(J26="","",(E10+E12+E19+E18)*K26) -> 0
A17: Prorata en % du DT H.T : | B17: =IF(S10="% DT HT",L13,0) -> 0 | C17: =IF(S23="% DT HT",L27,IF(S23="% st ht",O26,0)) -> 0 | D17: =IF(S10="% DT HT",D10*L13,IF(S10="% PV HT",0)) -> 0 | E17: =IF(S23="% DT HT",E10*L27,IF(S23="% PV HT",0)) -> 0
A18: Prorata en % du PV H.T : | B18: =IF(S10="% DT HT",0,IF(S10="% pv ht",J13,IF(R10="",""))) -> 0 | C18: =IF(S23="% DT HT",0,IF(S23="% pv ht",J27,IF(S23="% st ht",O27,IF(S23="","")))) -> 0 | D18: =IF(S10="% DT HT",0,IF(S10="% PV HT",(D10+D12+D19+D17))*K13) -> 0 | E18: =IF(S23="% DT HT",0,IF(S23="% PV HT",(E10+E12+E19+E17))*L13) -> 0 | F18: Montant travaux sous-traités | Q18: SOUS TRAITANT
A19: en % du D.T H.T. | B19: =IF(S9="% DT HT",L12,0) -> 0 | C19: =IF(S22="% PV HT",L26,0) -> 0 | D19: =IF(S9="% DT HT",D10*B19,IF(S9="% PV HT",0)) -> 0 | E19: =IF(S22="% DT HT",E10*L27,IF(S22="% PV HT",0)) -> 0
A20: Total F.M. | D20: =SUM(D16:D19) -> 0 | E20: =SUM(E16:E19) -> 0 | H20: % du D.S | J20: % du P.V H.T | L20: % du D.T | N20: % du P.R | O20: % ST H.T | Q20: FC : | R20: 0 | S20: % DS
A21: PRIX DE REVIENT PR | D21: =D10+D14+D20 -> 0 | E21: =E10+E14+E20 -> 0 | Q21: FG : | R21: 0 | S21: % DT HT
A22: Bénéfices et aléas | F22: Frais de chantier : | H22: =R20/100 -> 0 | Q22: FM : | R22: 0 | S22: % PV HT
A23: en % du prix de revient | B23: =IF(S11="% PR HT",N14,0) -> 0 | C23: =IF(S24="% PR HT",N28,0) -> 0 | D23: =IF(S11="% PR HT",D21*N14,IF(S11="% PV HT",0)) -> 0 | E23: =IF(S24="% PR HT",E21*C23,IF(S24="% PV HT",0)) -> 0 | Q23: =Q10 -> PRORATA : | R23: 0 | S23: % DT HT
A24: en % du prix de vente H.T. | B24: =IF(S11="% PV HT",J14,0) -> 0 | C24: =IF(S24="% PV HT",J28,0) -> 0 | D24: =IF(D23=0,D21*K14,"") -> 0 | E24: =IF(E23=0,E21*K28,"") -> 0 | F24: Frais généraux : | J24: =IF(S21="% pv ht",(R21/100),0) -> 0 | K24: =(100/(100-((J24+J26+J27+J28)*100)))*J24 -> 0 | L24: =IF(S21="% dt ht",(R21/100),0) -> 0 | O24: =IF(S21="% st ht",(R21/100),0) -> 0 | Q24: BE : | R24: 0 | S24: % PR HT
A25: Total Bénéfice | D25: =SUM(D23:D24) -> 0 | E25: =SUM(E23:E24) -> 0
A26: PRIX DE VENTE HT | D26: =D21+D25 -> 0 | E26: =E21+E25 -> 0 | F26: Frais de marchés : | J26: =IF(S22="% pv ht",(R22/100),0) -> 0 | K26: =(100/(100-((J24+J26+J27+J28)*100)))*J26 -> 0 | L26: =IF(S22="% dt ht",(R22/100),0) -> 0 | O26: =IF(S22="% st ht",(R22/100),0) -> 0
A27: T.V.A. taux | B27: 0.2 | D27: =D26*B27 -> 0 | E27: =E26*B27 -> 0 | F27: Prorata : | J27: =IF(S23="% pv ht",(R23/100),0) -> 0 | K27: =(100/(100-((J24+J26+J27+J28)*100)))*J27 -> 0 | L27: =IF(S23="% dt ht",(R23/100),0) -> 0 | O27: =IF(S23="% st ht",(R23/100),0) -> 0
A28: PRIX DE VENTE T.T.C. | D28: =D26+D27 -> 0 | E28: =SUM(E26:E27) -> 0 | F28: Bénéfices et aléas : | J28: =IF(S24="% pv ht",(R24/100),0) -> 0 | K28: =(100/(100-((J28)*100))*J28) -> 0 | N28: =IF(S24="% PR ht",(R24/100),0) -> 0
A29: PRIX DE VENTE TOTAL T.T.C. | D29: =SUM(D28:E28) -> 0 | R29: D²
A30: COEFFICIENTS DE VENTE HT
A31: Travaux entreprise Kc | B31: =D26/D4 -> #DIV/0!
A32: Travaux sous traités K1 | C32: =E26/E4 -> #DIV/0!
A33: MARGE BRUT | D33: =D20+D25 -> 0 | E33: =E20+E25 -> 0
